/* eslint-disable @typescript-eslint/no-unused-expressions, @typescript-eslint/no-unsafe-member-access, @typescript-eslint/no-unsafe-call, @typescript-eslint/no-unsafe-assignment, @typescript-eslint/require-await, @typescript-eslint/unbound-method, @typescript-eslint/restrict-template-expressions, @typescript-eslint/no-unsafe-return, @typescript-eslint/no-unsafe-argument, @typescript-eslint/prefer-promise-reject-errors, @typescript-eslint/no-base-to-string, @typescript-eslint/only-throw-error, @typescript-eslint/no-empty-object-type, @typescript-eslint/await-thenable, @typescript-eslint/no-floating-promises, @typescript-eslint/no-misused-promises, @typescript-eslint/naming-convention, @typescript-eslint/no-unnecessary-type-assertion, @typescript-eslint/no-unused-vars, require-await, no-unused-private-class-members, @typescript-eslint/prefer-promise-reject-errors */
/**
 * This error is thrown when the puller fails for any reason.
 */

export class PullError extends Error {
  name = 'PullError';
  // causedBy is used instead of cause, because while cause has been proposed as a
  // JavaScript language standard for this purpose (see
  // https://github.com/tc39/proposal-error-cause) current browser behavior is
  // inconsistent.
  causedBy?: Error | undefined;
  constructor(causedBy?: Error) {
    super('Failed to pull');
    this.causedBy = causedBy;
  }
}
